<?xml version="1.0" encoding="utf-8"?>
<!-- This URDF was automatically created by SolidWorks to URDF Exporter! Originally created by Stephen Brawner (brawner@gmail.com) 
     Commit Version: 1.6.0-1-g15f4949  Build Version: 1.6.7594.29634
     For more information, please see http://wiki.ros.org/sw_urdf_exporter -->
<robot
  name="youbot_gripper_simulation">
  <link
    name="base_holder_link">
    <inertial>
      <origin
        xyz="-0.015491495243161 0.0134058939577222 0.00371507655788619"
        rpy="0 0 0" />
      <mass
        value="0.382706237757779" />
      <inertia
        ixx="0.000195298769640711"
        ixy="-1.32167505207369E-08"
        ixz="-4.42404549334983E-08"
        iyy="0.000298217600026634"
        iyz="-4.97606731526423E-06"
        izz="0.000356774474911275" />
    </inertial>
    <visual>
      <origin
        xyz="0 0 0"
        rpy="0 0 0" />
      <geometry>
        <mesh
          filename="package://youbot_gripper_simulation/meshes/base_holder_link.STL" />
      </geometry>
      <material
        name="">
        <color
          rgba="0.792156862745098 0.819607843137255 0.933333333333333 1" />
      </material>
    </visual>
    <collision>
      <origin
        xyz="0 0 0"
        rpy="0 0 0" />
      <geometry>
        <mesh
          filename="package://youbot_gripper_simulation/meshes/base_holder_link.STL" />
      </geometry>
    </collision>
  </link>
  <link
    name="servo_right_link">
    <inertial>
      <origin
        xyz="0.020150145575314 0.0101 0.0198454858796802"
        rpy="0 0 0" />
      <mass
        value="0.0338275279922958" />
      <inertia
        ixx="5.70756586656377E-06"
        ixy="8.04231059094176E-23"
        ixz="8.86766496554433E-08"
        iyy="9.51111668532985E-06"
        iyz="-1.77762496590663E-22"
        izz="6.07620941885605E-06" />
    </inertial>
    <visual>
      <origin
        xyz="0 0 0"
        rpy="0 0 0" />
      <geometry>
        <mesh
          filename="package://youbot_gripper_simulation/meshes/servo_right_link.STL" />
      </geometry>
      <material
        name="">
        <color
          rgba="0.792156862745098 0.819607843137255 0.933333333333333 1" />
      </material>
    </visual>
    <collision>
      <origin
        xyz="0 0 0"
        rpy="0 0 0" />
      <geometry>
        <mesh
          filename="package://youbot_gripper_simulation/meshes/servo_right_link.STL" />
      </geometry>
    </collision>
  </link>
  <joint
    name="servo_right_joint"
    type="fixed">
    <origin
      xyz="-0.011391 0.0238 0.0564"
      rpy="1.5708 1.5708 0" />
    <parent
      link="base_holder_link" />
    <child
      link="servo_right_link" />
    <axis
      xyz="0 0 0" />
  </joint>
  <link
    name="finger_right_link">
    <inertial>
      <origin
        xyz="-0.00107193969229475 0.0273387226840809 -0.0229648619610665"
        rpy="0 0 0" />
      <mass
        value="0.219669857119581" />
      <inertia
        ixx="4.77780286431822E-05"
        ixy="-1.87672997759881E-06"
        ixz="3.56804581083201E-07"
        iyy="2.76422154312974E-05"
        iyz="-8.05261824668597E-07"
        izz="5.21594938423751E-05" />
    </inertial>
    <visual>
      <origin
        xyz="0 0 0"
        rpy="0 0 0" />
      <geometry>
        <mesh
          filename="package://youbot_gripper_simulation/meshes/finger_right_link.STL" />
      </geometry>
      <material
        name="">
        <color
          rgba="0.792156862745098 0.819607843137255 0.933333333333333 1" />
      </material>
    </visual>
    <collision>
      <origin
        xyz="0 0 0"
        rpy="0 0 0" />
      <geometry>
        <mesh
          filename="package://youbot_gripper_simulation/meshes/finger_right_link.STL" />
      </geometry>
    </collision>
  </link>
  <joint
    name="finger_right_joint"
    type="continuous">
    <origin
      xyz="0.0102 0.0101 0"
      rpy="3.1416 0 -1.669" />
    <parent
      link="servo_right_link" />
    <child
      link="finger_right_link" />
    <axis
      xyz="0 0 1" />
  </joint>
  <link
    name="servo_left_link">
    <inertial>
      <origin
        xyz="0.020150145575314 0.0101 0.0198454858796802"
        rpy="0 0 0" />
      <mass
        value="0.0338275279922958" />
      <inertia
        ixx="5.70756586656377E-06"
        ixy="5.68932882048631E-23"
        ixz="8.86766496554432E-08"
        iyy="9.51111668532985E-06"
        iyz="-9.56444602944626E-23"
        izz="6.07620941885605E-06" />
    </inertial>
    <visual>
      <origin
        xyz="0 0 0"
        rpy="0 0 0" />
      <geometry>
        <mesh
          filename="package://youbot_gripper_simulation/meshes/servo_left_link.STL" />
      </geometry>
      <material
        name="">
        <color
          rgba="0.792156862745098 0.819607843137255 0.933333333333333 1" />
      </material>
    </visual>
    <collision>
      <origin
        xyz="0 0 0"
        rpy="0 0 0" />
      <geometry>
        <mesh
          filename="package://youbot_gripper_simulation/meshes/servo_left_link.STL" />
      </geometry>
    </collision>
  </link>
  <joint
    name="servo_left_link"
    type="fixed">
    <origin
      xyz="-0.039791 0.0238 0.0564"
      rpy="1.5708 1.5708 0" />
    <parent
      link="base_holder_link" />
    <child
      link="servo_left_link" />
    <axis
      xyz="0 0 0" />
  </joint>
  <link
    name="finger_left_link">
    <inertial>
      <origin
        xyz="0.00107193969229474 0.027338722684081 -0.0229648619610666"
        rpy="0 0 0" />
      <mass
        value="0.219669857119581" />
      <inertia
        ixx="4.77780286431821E-05"
        ixy="1.8767299775988E-06"
        ixz="-3.56804581083246E-07"
        iyy="2.76422154312974E-05"
        iyz="-8.05261824668593E-07"
        izz="5.2159493842375E-05" />
    </inertial>
    <visual>
      <origin
        xyz="0 0 0"
        rpy="0 0 0" />
      <geometry>
        <mesh
          filename="package://youbot_gripper_simulation/meshes/finger_left_link.STL" />
      </geometry>
      <material
        name="">
        <color
          rgba="0.792156862745098 0.819607843137255 0.933333333333333 1" />
      </material>
    </visual>
    <collision>
      <origin
        xyz="0 0 0"
        rpy="0 0 0" />
      <geometry>
        <mesh
          filename="package://youbot_gripper_simulation/meshes/finger_left_link.STL" />
      </geometry>
    </collision>
  </link>
  <joint
    name="finger_left_joint"
    type="continuous">
    <origin
      xyz="0.0102 0.0101 0"
      rpy="3.1416 0 -1.6341" />
    <parent
      link="servo_left_link" />
    <child
      link="finger_left_link" />
    <axis
      xyz="0 0 1" />
  </joint>
</robot>