<?xml version="1.0" encoding="utf-8"?>
<!-- This URDF was automatically created by SolidWorks to URDF Exporter! Originally created by Stephen Brawner (brawner@gmail.com) 
     Commit Version: 1.6.0-1-g15f4949  Build Version: 1.6.7594.29634
     For more information, please see http://wiki.ros.org/sw_urdf_exporter -->
<robot
  name="new_gripper_urdf">
  <link
    name="base_holder_link">
    <inertial>
      <origin
        xyz="-0.0154913714783607 0.0138130469937227 -0.00019122623023348"
        rpy="0 0 0" />
      <mass
        value="0.325166075012768" />
      <inertia
        ixx="0.000176422818214742"
        ixy="-1.14630099641922E-09"
        ixz="-9.58997413681059E-09"
        iyy="0.000240392345030757"
        iyz="-7.04160665163785E-07"
        izz="0.000314342023674162" />
    </inertial>
    <visual>
      <origin
        xyz="0 0 0"
        rpy="0 0 0" />
      <geometry>
        <mesh
          filename="package://new_gripper_urdf/meshes/base_holder_link.STL" />
      </geometry>
      <material
        name="">
        <color
          rgba="1.0 0.4 0.0 1.0" />
      </material>
    </visual>
    <collision>
      <origin
        xyz="0 0 0"
        rpy="0 0 0" />
      <geometry>
        <mesh
          filename="package://new_gripper_urdf/meshes/base_holder_link.STL" />
      </geometry>
    </collision>
  </link>
  <link
    name="servo_left_link">
    <inertial>
      <origin
        xyz="0.020150145575314 0.0101 0.0198454858796802"
        rpy="0 0 0" />
      <mass
        value="0.0338275279922958" />
      <inertia
        ixx="5.70756586656377E-06"
        ixy="5.80148509440568E-23"
        ixz="8.86766496554433E-08"
        iyy="9.51111668532985E-06"
        iyz="-6.32864720294365E-23"
        izz="6.07620941885605E-06" />
    </inertial>
    <visual>
      <origin
        xyz="0 0 0"
        rpy="0 0 0" />
      <geometry>
        <mesh
          filename="package://new_gripper_urdf/meshes/servo_left_link.STL" />
      </geometry>
      <material
        name="">
        <color
          rgba="0.0 0.0 0.0 1.0" />
      </material>
    </visual>
    <collision>
      <origin
        xyz="0 0 0"
        rpy="0 0 0" />
      <geometry>
        <mesh
          filename="package://new_gripper_urdf/meshes/servo_left_link.STL" />
      </geometry>
    </collision>
  </link>
  <joint
    name="servo_left_joint"
    type="fixed">
    <origin
      xyz="-0.0397908009150208 0.0238 0.0564"
      rpy="1.5707963267949 1.5707963267949 0" />
    <parent
      link="base_holder_link" />
    <child
      link="servo_left_link" />
    <axis
      xyz="0 0 0" />
  </joint>
  <link
    name="left_finger_fastener_link">
    <inertial>
      <origin
        xyz="0.00226372174067158 0.0199992839781028 -0.0234471080962139"
        rpy="0 0 0" />
      <mass
        value="0.151196981912259" />
      <inertia
        ixx="2.85195555313607E-05"
        ixy="-1.97852751743602E-06"
        ixz="-3.56804581083221E-07"
        iyy="1.94075397459348E-05"
        iyz="-8.05261824668591E-07"
        izz="3.17989362126204E-05" />
    </inertial>
    <visual>
      <origin
        xyz="0 0 0"
        rpy="0 0 0" />
      <geometry>
        <mesh
          filename="package://new_gripper_urdf/meshes/left_finger_fastener_link.STL" />
      </geometry>
      <material
        name="">
        <color
          rgba="1.0 0.4 0.0 1.0" />
      </material>
    </visual>
    <collision>
      <origin
        xyz="0 0 0"
        rpy="0 0 0" />
      <geometry>
        <mesh
          filename="package://new_gripper_urdf/meshes/left_finger_fastener_link.STL" />
      </geometry>
    </collision>
  </link>
  <joint
    name="left_finger_fastener_joint"
    type="continuous">
    <origin
      xyz="0.0102000000000002 0.0101 0"
      rpy="3.14159265358979 0 -1.58659399800857" />
    <parent
      link="servo_left_link" />
    <child
      link="left_finger_fastener_link" />
    <axis
      xyz="0 0 1" />
  </joint>
  <link
    name="left_finger_link">
    <inertial>
      <origin
        xyz="0.0169959009662644 -0.0172451544705946 0.018"
        rpy="0 0 0" />
      <mass
        value="0.0684728752073224" />
      <inertia
        ixx="1.92584731118216E-05"
        ixy="3.85525749503484E-06"
        ixz="2.91277822181814E-20"
        iyy="8.23467568536262E-06"
        iyz="-1.04607349996278E-20"
        izz="2.03605576297548E-05" />
    </inertial>
    <visual>
      <origin
        xyz="0 0 0"
        rpy="0 0 0" />
      <geometry>
        <mesh
          filename="package://new_gripper_urdf/meshes/left_finger_link.STL" />
      </geometry>
      <material
        name="">
        <color
          rgba="1.0 1.0 1.0 1.0" />
      </material>
    </visual>
    <collision>
      <origin
        xyz="0 0 0"
        rpy="0 0 0" />
      <geometry>
        <mesh
          filename="package://new_gripper_urdf/meshes/left_finger_link.STL" />
      </geometry>
    </collision>
  </link>
  <joint
    name="left_finger_joint"
    type="fixed">
    <origin
      xyz="0.0154362314517575 0.0263000000000004 -0.0399"
      rpy="0 0 -3.14159265358979" />
    <parent
      link="left_finger_fastener_link" />
    <child
      link="left_finger_link" />
    <axis
      xyz="0 0 0" />
  </joint>
  <link
    name="servo_right_link">
    <inertial>
      <origin
        xyz="0.020150145575314 0.0101 0.0198454858796802"
        rpy="0 0 0" />
      <mass
        value="0.0338275279922958" />
      <inertia
        ixx="5.70756586656377E-06"
        ixy="7.85985176003018E-23"
        ixz="8.86766496554432E-08"
        iyy="9.51111668532985E-06"
        iyz="-1.83701156015215E-22"
        izz="6.07620941885605E-06" />
    </inertial>
    <visual>
      <origin
        xyz="0 0 0"
        rpy="0 0 0" />
      <geometry>
        <mesh
          filename="package://new_gripper_urdf/meshes/servo_right_link.STL" />
      </geometry>
      <material
        name="">
        <color
          rgba="0.0 0.0 0.0 1.0" />
      </material>
    </visual>
    <collision>
      <origin
        xyz="0 0 0"
        rpy="0 0 0" />
      <geometry>
        <mesh
          filename="package://new_gripper_urdf/meshes/servo_right_link.STL" />
      </geometry>
    </collision>
  </link>
  <joint
    name="servo_right_joint"
    type="fixed">
    <origin
      xyz="-0.0113908009150208 0.0238 0.0564"
      rpy="1.5707963267949 1.5707963267949 0" />
    <parent
      link="base_holder_link" />
    <child
      link="servo_right_link" />
    <axis
      xyz="0 0 0" />
  </joint>
  <link
    name="right_finger_fastener_link">
    <inertial>
      <origin
        xyz="-0.00226372174067153 0.0199992839781026 -0.0234471080962139"
        rpy="0 0 0" />
      <mass
        value="0.151196981912259" />
      <inertia
        ixx="2.85195555313607E-05"
        ixy="1.97852751743602E-06"
        ixz="3.56804581083222E-07"
        iyy="1.94075397459348E-05"
        iyz="-8.052618246686E-07"
        izz="3.17989362126203E-05" />
    </inertial>
    <visual>
      <origin
        xyz="0 0 0"
        rpy="0 0 0" />
      <geometry>
        <mesh
          filename="package://new_gripper_urdf/meshes/right_finger_fastener_link.STL" />
      </geometry>
      <material
        name="">
        <color
          rgba="1.0 0.4 0.0 1.0" />
      </material>
    </visual>
    <collision>
      <origin
        xyz="0 0 0"
        rpy="0 0 0" />
      <geometry>
        <mesh
          filename="package://new_gripper_urdf/meshes/right_finger_fastener_link.STL" />
      </geometry>
    </collision>
  </link>
  <joint
    name="right_finger_fastener_joint"
    type="continuous">
    <origin
      xyz="0.0102000000000001 0.0101 0"
      rpy="3.14159265358979 0 -1.58829722752844" />
    <parent
      link="servo_right_link" />
    <child
      link="right_finger_fastener_link" />
    <axis
      xyz="0 0 1" />
  </joint>
  <link
    name="right_finger_link">
    <inertial>
      <origin
        xyz="0.0169959009662644 -0.0172451544705946 0.018"
        rpy="0 0 0" />
      <mass
        value="0.0684728752073222" />
      <inertia
        ixx="1.92584731118215E-05"
        ixy="3.85525749503483E-06"
        ixz="2.57564826261444E-20"
        iyy="8.23467568536258E-06"
        iyz="-2.12579001275468E-21"
        izz="2.03605576297547E-05" />
    </inertial>
    <visual>
      <origin
        xyz="0 0 0"
        rpy="0 0 0" />
      <geometry>
        <mesh
          filename="package://new_gripper_urdf/meshes/right_finger_link.STL" />
      </geometry>
      <material
        name="">
        <color
          rgba="1.0 1.0 1.0 1.0" />
      </material>
    </visual>
    <collision>
      <origin
        xyz="0 0 0"
        rpy="0 0 0" />
      <geometry>
        <mesh
          filename="package://new_gripper_urdf/meshes/right_finger_link.STL" />
      </geometry>
    </collision>
  </link>
  <joint
    name="right_finger_joint"
    type="fixed">
    <origin
      xyz="-0.0154362314517573 0.0263 -0.00390000000000003"
      rpy="3.14159265358979 0 0" />
    <parent
      link="right_finger_fastener_link" />
    <child
      link="right_finger_link" />
    <axis
      xyz="0 0 0" />
  </joint>
  <link
    name="camera_holder_link">
    <inertial>
      <origin
        xyz="-0.0154558187135768 0.0264554443238969 0.00610502534126566"
        rpy="0 0 0" />
      <mass
        value="0.0575401627450105" />
      <inertia
        ixx="1.88760755233664E-05"
        ixy="6.42179161095357E-08"
        ixz="6.70844267074005E-09"
        iyy="4.24323271397149E-05"
        iyz="-4.2719184355183E-06"
        izz="5.78252549958773E-05" />
    </inertial>
    <visual>
      <origin
        xyz="0 0 0"
        rpy="0 0 0" />
      <geometry>
        <mesh
          filename="package://new_gripper_urdf/meshes/camera_holder_link.STL" />
      </geometry>
      <material
        name="">
        <color
          rgba="0.0 0.0 0.0 1.0" />
      </material>
    </visual>
    <collision>
      <origin
        xyz="0 0 0"
        rpy="0 0 0" />
      <geometry>
        <mesh
          filename="package://new_gripper_urdf/meshes/camera_holder_link.STL" />
      </geometry>
    </collision>
  </link>
  <joint
    name="camera_holder_joint"
    type="fixed">
    <origin
      xyz="-0.0309812074459294 0.0006459809840905 0.005"
      rpy="0 0 -3.14033747664133" />
    <parent
      link="base_holder_link" />
    <child
      link="camera_holder_link" />
    <axis
      xyz="0 0 0" />
  </joint>
</robot>
